Workbook
Name Slicer_City__Location: #N/A
Name Slicer_City__Location1: #N/A
Name Slicer_Industry_Vertical: #N/A
Name Slicer_Year: #N/A

Sheet README
A1: INDIAN STARTUP FUNDING ANALYSIS (2015–2020)
A6: Project Overview
A7: This project analyzes Indian startup funding data from 2015 to 2020
A8: to identify funding trends, industry performance, investor dominance,
A9: and city-wise capital distribution using Microsoft Excel.
A11: The analysis includes pivot-based summaries, lookup enrichment,
A12: and an interactive executive dashboard.
A14: Project Objectives
A15: • Analyze total funding trends over time
A16: • Identify top industries attracting investment
A17: • Determine leading investors by funding amount
A18: • Compare Angel vs VC funding contribution
... A45: Data Analytics Portfolio Project

Sheet Raw_data
A1: Sr No | B1: Date dd/mm/yyyy | C1: Startup Name | D1: Industry Vertical | E1: SubVertical | F1: City Location | G1: Investors Name | H1: InvestmentnType | I1: Amount in USD | J1: Remarks
A2: 1 | B2: 43839 | C2: BYJU’S | D2: E-Tech | E2: E-learning | F2: Bengaluru | G2: Tiger Global Management | H2: Private Equity Round | I2: 200000000
A3: 2 | B3: 43843 | C3: Shuttl | D3: Transportation | E3: App based shuttle service | F3: Gurgaon | G3: Susquehanna Growth Equity | H3: Series C | I3: 8048394
A4: 3 | B4: 43839 | C4: Mamaearth | D4: E-commerce | E4: Retailer of baby and toddler products | F4: Bengaluru | G4: Sequoia Capital India | H4: Series B | I4: 18358860
A5: 4 | B5: 43832 | C5: https://www.wealthbucket.in/ | D5: FinTech | E5: Online Investment | F5: New Delhi | G5: Vinod Khatumal | H5: Pre-series A | I5: 3000000
A6: 5 | B6: 43832 | C6: Fashor | D6: Fashion and Apparel | E6: Embroiled Clothes For Women | F6: Mumbai | G6: Sprout Venture Partners | H6: Seed Round | I6: 1800000
A7: 6 | B7: 43843 | C7: Pando | D7: Logistics | E7: Open-market, freight management platform | F7: Chennai | G7: Chiratae Ventures | H7: Series A | I7: 9000000
A8: 7 | B8: 43840 | C8: Zomato | D8: Hospitality | E8: Online Food Delivery Platform | F8: Gurgaon | G8: Ant Financial | H8: Private Equity Round | I8: 150000000
A9: 8 | B9: 43811 | C9: Ecozen | D9: Technology | E9: Agritech | F9: Pune | G9: Sathguru Catalyzer Advisors | H9: Series A | I9: 6000000
A10: 9 | B10: 43805 | C10: CarDekho | D10: E-Commerce | E10: Automobile | F10: Gurgaon | G10: Ping An Global Voyager Fund | H10: Series D | I10: 70000000
A11: 10 | B11: 43802 | C11: Dhruva Space | D11: Aerospace | E11: Satellite Communication | F11: Bengaluru | G11: Mumbai Angels, Ravikanth Reddy | H11: Seed | I11: 50000000
A12: 11 | B12: 43812 | C12: Rivigo | D12: Technology | E12: Logistics Services and Solutions | F12: Gurgaon | G12: SAIF Partners, Spring Canter Investment Ltd. | H12: Series F | I12: 20000000
A13: 12 | B13: 43816 | C13: Healthians | D13: B2B-focused foodtech startup | E13: Food Solutions For Corporate | F13: Bengaluru | G13: Paytm, NPTK, Sabre Partners and Neoplux | H13: Series C | I13: 12000000
A14: 13 | B14: 43815 | C14: Licious | D14: E-Commerce | E14: Online Meat And Seafood Ordering Startup | F14: Bengaluru | G14: Vertex Growth Fund | H14: Series E | I14: 30000000
A15: 14 | B15: 43815 | C15: InCred | D15: Finance | E15: Non-Banking Financial Company | F15: Mumbai | H15: Debt Funding | I15: 5900000
A16: 15 | B16: 43813 | C16: Trell | D16: Video | E16: Experience Discovery Platform | F16: Bengaluru | G16: Ruizheng Investment | H16: Seed Round | I16: 2000000
A17: 16 | B17: 43810 | C17: Rein Games | D17: Gaming | E17: Real money based gaming startup | F17: Noida | G17: Manipal Education and Medical Group (MEMG) | H17: Seed Round | I17: 50000000
A18: 17 | B18: 43819 | C18: Lenskart.com | D18: E-Commerce | E18: Online Eyewear Shopping Portal | F18: Faridabad | G18: SoftBank Vision Fund | H18: Series G | I18: 231000000
A19: 18 | B19: 43782 | C19: Freshworks | D19: Software | E19: Business and customer engagement tools | F19: San Francisco | G19: Sequoia, CapitalG, Accel | H19: Series H | I19: 150000000
A20: 19 | B20: 43783 | C20: Misters | D20: Health and wellness | E20: Men's Health and Wellness brand | F20: Gurgaon | G20: Sauce.vc, Rainforest Ventures | H20: Series B | I20: 486000
A21: 20 | B21: 43782 | C21: Sunstone Eduversity Pvt. Ltd | D21: Education | E21: Elearning | F21: Gurgaon | G21: Prime Venture Partners, LetsVenture, PS1 Venture and GlobalLogic co-founder Rajul Garg | H21: Seed | I21: 1500000
A22: 21 | B22: 43786 | C22: Burger Singh | D22: Food and Beverage | E22: Indian Burger Brand | F22: Gurgaon | G22: RB Investments | H22: Venture | I22: undisclosed
A23: 22 | B23: 43787 | C23: Healthians | D23: Health and Wellness | E23: Healthcare services | F23: Gurgaon | G23: DG Daiwa Ventures, DG Incubation | H23: Series B | I23: 12000000
A24: 23 | B24: 43784 | C24: Ninjacart | D24: B2B Marketing | E24: Agritech | F24: Bengaluru | G24: Trifecta Capital Advisors | H24: Debt Funding | I24: 26000000
A25: 24 | B25: 43789 | C25: Aye Finance | D25: FinTech | E25: Financial Services To MSMEs | F25: Gurgaon | G25: FinTech | H25: Debt Funding | I25: 17411265
A26: 25 | B26: 43781 | C26: SuperGaming | D26: Video Games | E26: Social gaming platform | F26: Pune | G26: Dream Incubator | H26: Seed Funding | I26: 1300000
A27: 26 | B27: 43789 | C27: Clumio | D27: SaaS | E27: Recovery software | F27: San Jose, | G27: Altimeter Capital, Sutter Hill Ventures | H27: Series C | I27: 135000000
A28: 27 | B28: 43780 | C28: eBikeGo | D28: Last Mile Transportation | E28: Electric bike rental | F28: Amritsar | G28: Startup Buddy | H28: Seed | I28: 300000
A29: 28 | B29: 43788 | C29: Digital Mall Asia | D29: E-Commerce | E29: Virtual e-commerce platform | F29: Delhi | G29: Amour Infrastructure | H29: Seed Funding | I29: 220000000
A30: 29 | B30: 43787 | C30: Medikabazaar | D30: Healthcare | E30: B2B platform for medical supplies | F30: Mumbai | G30: Ackermans & van Haaren, HealthQuad, Rebright Partners, Toppan Printing | H30: Series B | I30: 15800000
A31: 30 | B31: 43784 | C31: Vogo Automotive | D31: Last Mile Transportation | E31: Scooter sharing app | F31: Kormangala | G31: Matrix Partners, Stellaris Venture Partners, Kalaari Capital | H31: Series B | I31: 283000000
A32: 31 | B32: 43788 | C32: Furtados School of Music | D32: Education | E32: Music Education | F32: Tulangan | G32: IAN Fund and DSG Consumer Partners | I32: 200000000
A33: 32 | B33: 43794 | C33: Paytm | D33: FinTech | E33: Mobile Wallet | F33: Noida | G33: Vijay Shekhar Sharma | H33: Funding Round | I33: 1000000000
A34: 33 | B34: 43742 | C34: Dunzo | D34: Customer Service | E34: Delivery Service | F34: Bengaluru | G34: Lightbox | H34: Series D | I34: 45000000
A35: 34 | B35: 43740 | C35: Udaan | D35: B2B | E35: Business development | F35: Bengaluru | G35: Altimeter Capital, DST Global | H35: Series D | I35: 585000000
A36: 35 | B36: 43759 | C36: The Man Company | D36: Consumer Goods | E36: Beauty and Grooming | F36: Gurgaon | G36: Ayushmann Khurana | H36: Corporate Round | I36: unknown
A37: 36 | B37: 43713 | C37: FPL Technologies | D37: FinTech | E37: Financial Services | F37: Pune | G37: Matrix Partners India, Sequoia India | H37: Maiden Round | I37: 4500000
A38: 37 | B38: 43712 | C38: Cashflo | D38: FinTech | E38: Invoice discounting platform and SME lending marketplace | F38: Mumbai | G38: SAIF Partners | H38: Series A | I38: 3300000
A39: 38 | B39: 43712 | C39: Digital F5 | D39: Advertising, Marketing | E39: Digital marketing firm | F39: Mumbai | G39: TIW Private Equity | H39: Private Equity Round | I39: 6000000
A40: 39 | B40: 43712 | C40: 3rdFlix | D40: SaaS | E40: Education Technology | F40: Hyderabad | G40: Exfinity Venture Partners | H40: pre-series A | I40: 5000000
...

Sheet Data_Cleaning
A1: Sr No. | B1: Date | C1: Startup Name | D1: Industry Vertical | E1: SubVertical | F1: City Location | G1: Investors Name | H1: Investment Type | I1: Amount in USD | J1: Remarks | K1: Funding Range | L1: Startup City | M1: Investor Type | N1: Year
A2: 1 | B2: 43839 | C2: Byju’S | D2: E-Tech | E2: E-Learning | F2: Bangalore | G2: Tiger Global Management | H2: Private Equity Round | I2: 200000000 | J2: N/A | K2: >10M | L2: =IFERROR(_xlfn.XLOOKUP(Table1[[#This Row],[Startup Name]],Reference_Tables!$A$5:$A$3048,Reference_Tables!$B$5:$B$3048,"N/A",0),"N/A") -> Gurugram | M2: =IFERROR(_xlfn.XLOOKUP(Table1[[#This Row],[Investors Name]],Reference_Tables!$E$5:$E$3048,Reference_Tables!$F$5:$F$3048,"N/A",0),"N/A") -> Angel | N2: =YEAR(Table1[[#This Row],[Date]]) -> 2020
A3: 2 | B3: 43843 | C3: Shuttl | D3: Transportation | E3: App Based Shuttle Service | F3: Gurugram | G3: Susquehanna Growth Equity | H3: Series C | I3: 8048394 | J3: N/A | K3: 1–10M | L3: =IFERROR(_xlfn.XLOOKUP(Table1[[#This Row],[Startup Name]],Reference_Tables!$A$5:$A$3048,Reference_Tables!$B$5:$B$3048,"N/A",0),"N/A") -> Gurugram | M3: =IFERROR(_xlfn.XLOOKUP(Table1[[#This Row],[Investors Name]],Reference_Tables!$E$5:$E$3048,Reference_Tables!$F$5:$F$3048,"N/A",0),"N/A") -> VC | N3: =YEAR(Table1[[#This Row],[Date]]) -> 2020
A4: 3 | B4: 43839 | C4: Mamaearth | D4: E-Commerce | E4: Retailer Of Baby And Toddler Products | F4: Bangalore | G4: Sequoia Capital India | H4: Series B | I4: 18358860 | J4: N/A | K4: >10M | L4: =IFERROR(_xlfn.XLOOKUP(Table1[[#This Row],[Startup Name]],Reference_Tables!$A$5:$A$3048,Reference_Tables!$B$5:$B$3048,"N/A",0),"N/A") -> Chennai | M4: =IFERROR(_xlfn.XLOOKUP(Table1[[#This Row],[Investors Name]],Reference_Tables!$E$5:$E$3048,Reference_Tables!$F$5:$F$3048,"N/A",0),"N/A") -> VC | N4: =YEAR(Table1[[#This Row],[Date]]) -> 2020
A5: 4 | B5: 43832 | C5: Wealthbucket | D5: Fintech | E5: Online Investment | F5: Delhi | G5: Vinod Khatumal | H5: Pre-Series A | I5: 3000000 | J5: N/A | K5: 1–10M | L5: =IFERROR(_xlfn.XLOOKUP(Table1[[#This Row],[Startup Name]],Reference_Tables!$A$5:$A$3048,Reference_Tables!$B$5:$B$3048,"N/A",0),"N/A") -> Patna | M5: =IFERROR(_xlfn.XLOOKUP(Table1[[#This Row],[Investors Name]],Reference_Tables!$E$5:$E$3048,Reference_Tables!$F$5:$F$3048,"N/A",0),"N/A") -> Angel | N5: =YEAR(Table1[[#This Row],[Date]]) -> 2020
A6: 5 | B6: 43832 | C6: Fashor | D6: Fashion And Apparel | E6: Embroiled Clothes For Women | F6: Mumbai | G6: Sprout Venture Partners | H6: Seed Round | I6: 1800000 | J6: N/A | K6: 1–10M | L6: =IFERROR(_xlfn.XLOOKUP(Table1[[#This Row],[Startup Name]],Reference_Tables!$A$5:$A$3048,Reference_Tables!$B$5:$B$3048,"N/A",0),"N/A") -> Ranchi | M6: =IFERROR(_xlfn.XLOOKUP(Table1[[#This Row],[Investors Name]],Reference_Tables!$E$5:$E$3048,Reference_Tables!$F$5:$F$3048,"N/A",0),"N/A") -> VC | N6: =YEAR(Table1[[#This Row],[Date]]) -> 2020
A7: 6 | B7: 43843 | C7: Pando | D7: Logistics | E7: Open-Market, Freight Management Platform | F7: Chennai | G7: Chiratae Ventures | H7: Series A | I7: 9000000 | J7: N/A | K7: 1–10M | L7: =IFERROR(_xlfn.XLOOKUP(Table1[[#This Row],[Startup Name]],Reference_Tables!$A$5:$A$3048,Reference_Tables!$B$5:$B$3048,"N/A",0),"N/A") -> Lucknow | M7: =IFERROR(_xlfn.XLOOKUP(Table1[[#This Row],[Investors Name]],Reference_Tables!$E$5:$E$3048,Reference_Tables!$F$5:$F$3048,"N/A",0),"N/A") -> VC | N7: =YEAR(Table1[[#This Row],[Date]]) -> 2020
A8: 7 | B8: 43840 | C8: Zomato | D8: Hospitality | E8: Online Food Delivery Platform | F8: Gurugram | G8: Ant Finacial | H8: Private Equity Round | I8: 150000000 | J8: N/A | K8: >10M | L8: =IFERROR(_xlfn.XLOOKUP(Table1[[#This Row],[Startup Name]],Reference_Tables!$A$5:$A$3048,Reference_Tables!$B$5:$B$3048,"N/A",0),"N/A") -> Dehradun | M8: =IFERROR(_xlfn.XLOOKUP(Table1[[#This Row],[Investors Name]],Reference_Tables!$E$5:$E$3048,Reference_Tables!$F$5:$F$3048,"N/A",0),"N/A") -> Angel | N8: =YEAR(Table1[[#This Row],[Date]]) -> 2020
A9: 8 | B9: 43811 | C9: Ecozen | D9: Technology | E9: Agritech | F9: Pune | G9: Sathguru Catalyzer Advisors | H9: Series A | I9: 6000000 | J9: N/A | K9: 1–10M | L9: =IFERROR(_xlfn.XLOOKUP(Table1[[#This Row],[Startup Name]],Reference_Tables!$A$5:$A$3048,Reference_Tables!$B$5:$B$3048,"N/A",0),"N/A") -> Indore | M9: =IFERROR(_xlfn.XLOOKUP(Table1[[#This Row],[Investors Name]],Reference_Tables!$E$5:$E$3048,Reference_Tables!$F$5:$F$3048,"N/A",0),"N/A") -> Angel | N9: =YEAR(Table1[[#This Row],[Date]]) -> 2019
A10: 9 | B10: 43805 | C10: Cardekho | D10: E-Commerce | E10: Automobile | F10: Gurugram | G10: Ping An Global Voyager Fund | H10: Series D | I10: 70000000 | J10: N/A | K10: >10M | L10: =IFERROR(_xlfn.XLOOKUP(Table1[[#This Row],[Startup Name]],Reference_Tables!$A$5:$A$3048,Reference_Tables!$B$5:$B$3048,"N/A",0),"N/A") -> Ranchi | M10: =IFERROR(_xlfn.XLOOKUP(Table1[[#This Row],[Investors Name]],Reference_Tables!$E$5:$E$3048,Reference_Tables!$F$5:$F$3048,"N/A",0),"N/A") -> VC | N10: =YEAR(Table1[[#This Row],[Date]]) -> 2019
A11: 10 | B11: 43802 | C11: Dhruva Space | D11: Aerospace | E11: Satellite Communication | F11: Bangalore | G11: Mumbai Angels, Ravikanth Reddy | H11: Seed | I11: 50000000 | J11: N/A | K11: >10M | L11: =IFERROR(_xlfn.XLOOKUP(Table1[[#This Row],[Startup Name]],Reference_Tables!$A$5:$A$3048,Reference_Tables!$B$5:$B$3048,"N/A",0),"N/A") -> Nagpur | M11: =IFERROR(_xlfn.XLOOKUP(Table1[[#This Row],[Investors Name]],Reference_Tables!$E$5:$E$3048,Reference_Tables!$F$5:$F$3048,"N/A",0),"N/A") -> Angel | N11: =YEAR(Table1[[#This Row],[Date]]) -> 2019
A12: 11 | B12: 43812 | C12: Rivigo | D12: Technology | E12: Logistics Services And Solutions | F12: Gurugram | G12: Saif Partners, Spring Canter Investment Ltd. | H12: Series F | I12: 20000000 | J12: N/A | K12: >10M | L12: =IFERROR(_xlfn.XLOOKUP(Table1[[#This Row],[Startup Name]],Reference_Tables!$A$5:$A$3048,Reference_Tables!$B$5:$B$3048,"N/A",0),"N/A") -> Bhopal | M12: =IFERROR(_xlfn.XLOOKUP(Table1[[#This Row],[Investors Name]],Reference_Tables!$E$5:$E$3048,Reference_Tables!$F$5:$F$3048,"N/A",0),"N/A") -> VC | N12: =YEAR(Table1[[#This Row],[Date]]) -> 2019
A13: 12 | B13: 43816 | C13: Healthians | D13: B2B-Focused Foodtech Startup | E13: Food Solutions For Corporate | F13: Bangalore | G13: Paytm, Nptk, Sabre Partners And Neoplux | H13: Series C | I13: 12000000 | J13: N/A | K13: >10M | L13: =IFERROR(_xlfn.XLOOKUP(Table1[[#This Row],[Startup Name]],Reference_Tables!$A$5:$A$3048,Reference_Tables!$B$5:$B$3048,"N/A",0),"N/A") -> Chandigarh | M13: =IFERROR(_xlfn.XLOOKUP(Table1[[#This Row],[Investors Name]],Reference_Tables!$E$5:$E$3048,Reference_Tables!$F$5:$F$3048,"N/A",0),"N/A") -> VC | N13: =YEAR(Table1[[#This Row],[Date]]) -> 2019
A14: 13 | B14: 43815 | C14: Licious | D14: E-Commerce | E14: Online Meat And Seafood Ordering Startup | F14: Bangalore | G14: Vertex Growth Fund | H14: Series E | I14: 30000000 | J14: N/A | K14: >10M | L14: =IFERROR(_xlfn.XLOOKUP(Table1[[#This Row],[Startup Name]],Reference_Tables!$A$5:$A$3048,Reference_Tables!$B$5:$B$3048,"N/A",0),"N/A") -> Mysuru | M14: =IFERROR(_xlfn.XLOOKUP(Table1[[#This Row],[Investors Name]],Reference_Tables!$E$5:$E$3048,Reference_Tables!$F$5:$F$3048,"N/A",0),"N/A") -> VC | N14: =YEAR(Table1[[#This Row],[Date]]) -> 2019
A15: 14 | B15: 43815 | C15: Incred | D15: Finace | E15: Non-Banking Finacial Company | F15: Mumbai | G15: N/A | H15: Debt Funding | I15: 5900000 | J15: N/A | K15: 1–10M | L15: =IFERROR(_xlfn.XLOOKUP(Table1[[#This Row],[Startup Name]],Reference_Tables!$A$5:$A$3048,Reference_Tables!$B$5:$B$3048,"N/A",0),"N/A") -> Ahmedabad | M15: N/A | N15: =YEAR(Table1[[#This Row],[Date]]) -> 2019
A16: 15 | B16: 43813 | C16: Trell | D16: Video | E16: Experience Discovery Platform | F16: Bangalore | G16: Ruizheng Investment | H16: Seed Round | I16: 2000000 | J16: N/A | K16: 1–10M | L16: =IFERROR(_xlfn.XLOOKUP(Table1[[#This Row],[Startup Name]],Reference_Tables!$A$5:$A$3048,Reference_Tables!$B$5:$B$3048,"N/A",0),"N/A") -> Patna | M16: =IFERROR(_xlfn.XLOOKUP(Table1[[#This Row],[Investors Name]],Reference_Tables!$E$5:$E$3048,Reference_Tables!$F$5:$F$3048,"N/A",0),"N/A") -> VC | N16: =YEAR(Table1[[#This Row],[Date]]) -> 2019
A17: 16 | B17: 43810 | C17: Rein Games | D17: Gaming | E17: Real Money Based Gaming Startup | F17: Noida | G17: Manipal Education And Medical Group (Memg) | H17: Seed Round | I17: 50000000 | J17: N/A | K17: >10M | L17: =IFERROR(_xlfn.XLOOKUP(Table1[[#This Row],[Startup Name]],Reference_Tables!$A$5:$A$3048,Reference_Tables!$B$5:$B$3048,"N/A",0),"N/A") -> Bhubaneswar | M17: =IFERROR(_xlfn.XLOOKUP(Table1[[#This Row],[Investors Name]],Reference_Tables!$E$5:$E$3048,Reference_Tables!$F$5:$F$3048,"N/A",0),"N/A") -> Corporate | N17: =YEAR(Table1[[#This Row],[Date]]) -> 2019
A18: 17 | B18: 43819 | C18: Lenskart.Com | D18: E-Commerce | E18: Online Eyewear Shopping Portal | F18: Faridabad | G18: Softbank Vision Fund | H18: Series G | I18: 231000000 | J18: N/A | K18: >10M | L18: =IFERROR(_xlfn.XLOOKUP(Table1[[#This Row],[Startup Name]],Reference_Tables!$A$5:$A$3048,Reference_Tables!$B$5:$B$3048,"N/A",0),"N/A") -> Vadodara | M18: =IFERROR(_xlfn.XLOOKUP(Table1[[#This Row],[Investors Name]],Reference_Tables!$E$5:$E$3048,Reference_Tables!$F$5:$F$3048,"N/A",0),"N/A") -> VC | N18: =YEAR(Table1[[#This Row],[Date]]) -> 2019
A19: 18 | B19: 43782 | C19: Freshworks | D19: Software | E19: Business And Customer Engagement Tools | F19: San Francisco | G19: Sequoia, Capitalg, Accel | H19: Series H | I19: 150000000 | J19: N/A | K19: >10M | L19: =IFERROR(_xlfn.XLOOKUP(Table1[[#This Row],[Startup Name]],Reference_Tables!$A$5:$A$3048,Reference_Tables!$B$5:$B$3048,"N/A",0),"N/A") -> Dehradun | M19: =IFERROR(_xlfn.XLOOKUP(Table1[[#This Row],[Investors Name]],Reference_Tables!$E$5:$E$3048,Reference_Tables!$F$5:$F$3048,"N/A",0),"N/A") -> VC | N19: =YEAR(Table1[[#This Row],[Date]]) -> 2019
A20: 19 | B20: 43783 | C20: Misters | D20: Health And Wellness | E20: Men'S Health And Wellness Brand | F20: Gurugram | G20: Sauce.Vc, Rainforest Ventures | H20: Series B | I20: 486000 | J20: N/A | K20: <1M | L20: =IFERROR(_xlfn.XLOOKUP(Table1[[#This Row],[Startup Name]],Reference_Tables!$A$5:$A$3048,Reference_Tables!$B$5:$B$3048,"N/A",0),"N/A") -> Mysuru | M20: =IFERROR(_xlfn.XLOOKUP(Table1[[#This Row],[Investors Name]],Reference_Tables!$E$5:$E$3048,Reference_Tables!$F$5:$F$3048,"N/A",0),"N/A") -> VC | N20: =YEAR(Table1[[#This Row],[Date]]) -> 2019
A21: 20 | B21: 43782 | C21: Sunstone Eduversity Pvt. Ltd | D21: Education | E21: Elearning | F21: Gurugram | G21: Prime Venture Partners, Letsventure, Ps1 Venture And Globallogic Co-Founder Rajul Garg | H21: Seed | I21: 1500000 | J21: N/A | K21: 1–10M | L21: =IFERROR(_xlfn.XLOOKUP(Table1[[#This Row],[Startup Name]],Reference_Tables!$A$5:$A$3048,Reference_Tables!$B$5:$B$3048,"N/A",0),"N/A") -> Ahmedabad | M21: =IFERROR(_xlfn.XLOOKUP(Table1[[#This Row],[Investors Name]],Reference_Tables!$E$5:$E$3048,Reference_Tables!$F$5:$F$3048,"N/A",0),"N/A") -> VC | N21: =YEAR(Table1[[#This Row],[Date]]) -> 2019
A22: 21 | B22: 43786 | C22: Burger Singh | D22: Food And Beverage | E22: Indian Burger Brand | F22: Gurugram | G22: Rb Investments | H22: Venture | I22: 0 | J22: N/A | K22: N/A | L22: =IFERROR(_xlfn.XLOOKUP(Table1[[#This Row],[Startup Name]],Reference_Tables!$A$5:$A$3048,Reference_Tables!$B$5:$B$3048,"N/A",0),"N/A") -> Visakhapatnam | M22: =IFERROR(_xlfn.XLOOKUP(Table1[[#This Row],[Investors Name]],Reference_Tables!$E$5:$E$3048,Reference_Tables!$F$5:$F$3048,"N/A",0),"N/A") -> VC | N22: =YEAR(Table1[[#This Row],[Date]]) -> 2019
A23: 22 | B23: 43787 | C23: Healthians | D23: Health And Wellness | E23: Healthcare Services | F23: Gurugram | G23: Dg Daiwa Ventures, Dg Incubation | H23: Series B | I23: 12000000 | J23: N/A | K23: >10M | L23: =IFERROR(_xlfn.XLOOKUP(Table1[[#This Row],[Startup Name]],Reference_Tables!$A$5:$A$3048,Reference_Tables!$B$5:$B$3048,"N/A",0),"N/A") -> Chandigarh | M23: =IFERROR(_xlfn.XLOOKUP(Table1[[#This Row],[Investors Name]],Reference_Tables!$E$5:$E$3048,Reference_Tables!$F$5:$F$3048,"N/A",0),"N/A") -> VC | N23: =YEAR(Table1[[#This Row],[Date]]) -> 2019
A24: 23 | B24: 43784 | C24: Ninjacart | D24: B2B Marketing | E24: Agritech | F24: Bangalore | G24: Trifecta Capital Advisors | H24: Debt Funding | I24: 26000000 | J24: N/A | K24: >10M | L24: =IFERROR(_xlfn.XLOOKUP(Table1[[#This Row],[Startup Name]],Reference_Tables!$A$5:$A$3048,Reference_Tables!$B$5:$B$3048,"N/A",0),"N/A") -> Mumbai | M24: =IFERROR(_xlfn.XLOOKUP(Table1[[#This Row],[Investors Name]],Reference_Tables!$E$5:$E$3048,Reference_Tables!$F$5:$F$3048,"N/A",0),"N/A") -> VC | N24: =YEAR(Table1[[#This Row],[Date]]) -> 2019
A25: 24 | B25: 43789 | C25: Aye Finace | D25: Fintech | E25: Finacial Services To Msmes | F25: Gurugram | G25: Fintech | H25: Debt Funding | I25: 17411265 | J25: N/A | K25: >10M | L25: =IFERROR(_xlfn.XLOOKUP(Table1[[#This Row],[Startup Name]],Reference_Tables!$A$5:$A$3048,Reference_Tables!$B$5:$B$3048,"N/A",0),"N/A") -> Nagpur | M25: =IFERROR(_xlfn.XLOOKUP(Table1[[#This Row],[Investors Name]],Reference_Tables!$E$5:$E$3048,Reference_Tables!$F$5:$F$3048,"N/A",0),"N/A") -> Angel | N25: =YEAR(Table1[[#This Row],[Date]]) -> 2019
A26: 25 | B26: 43781 | C26: Supergaming | D26: Video Games | E26: Social Gaming Platform | F26: Pune | G26: Dream Incubator | H26: Seed Funding | I26: 1300000 | J26: N/A | K26: 1–10M | L26: =IFERROR(_xlfn.XLOOKUP(Table1[[#This Row],[Startup Name]],Reference_Tables!$A$5:$A$3048,Reference_Tables!$B$5:$B$3048,"N/A",0),"N/A") -> Kolkata | M26: =IFERROR(_xlfn.XLOOKUP(Table1[[#This Row],[Investors Name]],Reference_Tables!$E$5:$E$3048,Reference_Tables!$F$5:$F$3048,"N/A",0),"N/A") -> Angel | N26: =YEAR(Table1[[#This Row],[Date]]) -> 2019
A27: 26 | B27: 43789 | C27: Clumio | D27: Saas | E27: Recovery Software | F27: San Jose, | G27: Altimeter Capital, Sutter Hill Ventures | H27: Series C | I27: 135000000 | J27: N/A | K27: >10M | L27: =IFERROR(_xlfn.XLOOKUP(Table1[[#This Row],[Startup Name]],Reference_Tables!$A$5:$A$3048,Reference_Tables!$B$5:$B$3048,"N/A",0),"N/A") -> Guwahati | M27: =IFERROR(_xlfn.XLOOKUP(Table1[[#This Row],[Investors Name]],Reference_Tables!$E$5:$E$3048,Reference_Tables!$F$5:$F$3048,"N/A",0),"N/A") -> VC | N27: =YEAR(Table1[[#This Row],[Date]]) -> 2019
... A47: 46 | B47: 43678 | C47: Progcap | D47: Finace | E47: Supply Chain Management | F47: Delhi | G47: Sequoia India | H47: Series A | I47: 5000000 | J47: N/A | K47: 1–10M | L47: =IFERROR(_xlfn.XLOOKUP(Table1[[#This Row],[Startup Name]],Reference_Tables!$A$5:$A$3048,Reference_Tables!$B$5:$B$3048,"N/A",0),"N/A") -> Dehradun | M47: =IFERROR(_xlfn.XLOOKUP(Table1[[#This Row],[Investors Name]],Reference_Tables!$E$5:$E$3048,Reference_Tables!$F$5:$F$3048,"N/A",0),"N/A") -> Angel | N47: =YEAR(Table1[[#This Row],[Date]]) -> 2019
A48: 47 | B48: 43678 | C48: Mypetrolpump | D48: Retail | E48: Fuel Delivery | F48: Bangalore | G48: N/A | H48: Seed Funding Round | I48: 1600000 | J48: N/A | K48: 1–10M | L48: =IFERROR(_xlfn.XLOOKUP(Table1[[#This Row],[Startup Name]],Reference_Tables!$A$5:$A$3048,Reference_Tables!$B$5:$B$3048,"N/A",0),"N/A") -> Coimbatore | M48: N/A | N48: =YEAR(Table1[[#This Row],[Date]]) -> 2019
A49: 48 | B49: 43678 | C49: Alteria Capital | D49: Finace | E49: Vc Funds | F49: Mumbai | G49: Azim Premji, Binny Bansal | H49: Single Venture | I49: 140000000 | J49: N/A | K49: >10M | L49: =IFERROR(_xlfn.XLOOKUP(Table1[[#This Row],[Startup Name]],Reference_Tables!$A$5:$A$3048,Reference_Tables!$B$5:$B$3048,"N/A",0),"N/A") -> Kanpur | M49: =IFERROR(_xlfn.XLOOKUP(Table1[[#This Row],[Investors Name]],Reference_Tables!$E$5:$E$3048,Reference_Tables!$F$5:$F$3048,"N/A",0),"N/A") -> Angel | N49: =YEAR(Table1[[#This Row],[Date]]) -> 2019
A50: 49 | B50: 43678 | C50: Pine Labs | D50: Information Technology | E50: Last-Mile Retail Transaction Technology | F50: Noida | G50: Pine Labs Pte Ltd | H50: Corporate Round | I50: 38080000 | J50: N/A | K50: >10M | L50: =IFERROR(_xlfn.XLOOKUP(Table1[[#This Row],[Startup Name]],Reference_Tables!$A$5:$A$3048,Reference_Tables!$B$5:$B$3048,"N/A",0),"N/A") -> Visakhapatnam | M50: =IFERROR(_xlfn.XLOOKUP(Table1[[#This Row],[Investors Name]],Reference_Tables!$E$5:$E$3048,Reference_Tables!$F$5:$F$3048,"N/A",0),"N/A") -> Corporate | N50: =YEAR(Table1[[#This Row],[Date]]) -> 2019
A51: 50 | B51: 43689 | C51: Meesho | D51: E-Commerce | E51: Social Commerce | F51: Bangalore | G51: Naspers | H51: Series D | I51: 125000000 | J51: N/A | K51: >10M | L51: =IFERROR(_xlfn.XLOOKUP(Table1[[#This Row],[Startup Name]],Reference_Tables!$A$5:$A$3048,Reference_Tables!$B$5:$B$3048,"N/A",0),"N/A") -> Vadodara | M51: =IFERROR(_xlfn.XLOOKUP(Table1[[#This Row],[Investors Name]],Reference_Tables!$E$5:$E$3048,Reference_Tables!$F$5:$F$3048,"N/A",0),"N/A") -> Corporate | N51: =YEAR(Table1[[#This Row],[Date]]) -> 2019
A52: 51 | B52: 43690 | C52: Cars24 | D52: E-Commerce | E52: Car Retail | F52: Gurugram | G52: Ms Dhoni | H52: Series D | I52: 11000000 | J52: N/A | K52: >10M | L52: =IFERROR(_xlfn.XLOOKUP(Table1[[#This Row],[Startup Name]],Reference_Tables!$A$5:$A$3048,Reference_Tables!$B$5:$B$3048,"N/A",0),"N/A") -> Noida | M52: =IFERROR(_xlfn.XLOOKUP(Table1[[#This Row],[Investors Name]],Reference_Tables!$E$5:$E$3048,Reference_Tables!$F$5:$F$3048,"N/A",0),"N/A") -> Angel | N52: =YEAR(Table1[[#This Row],[Date]]) -> 2019
A53: 52 | B53: 43690 | C53: Uniphore | D53: Customer Service Platform | E53: Conversational Ai | F53: Palo Alto | G53: March Capital Partners | H53: Series C | I53: 51000000 | J53: N/A | K53: >10M | L53: =IFERROR(_xlfn.XLOOKUP(Table1[[#This Row],[Startup Name]],Reference_Tables!$A$5:$A$3048,Reference_Tables!$B$5:$B$3048,"N/A",0),"N/A") -> Bhubaneswar | M53: =IFERROR(_xlfn.XLOOKUP(Table1[[#This Row],[Investors Name]],Reference_Tables!$E$5:$E$3048,Reference_Tables!$F$5:$F$3048,"N/A",0),"N/A") -> VC | N53: =YEAR(Table1[[#This Row],[Date]]) -> 2019
A54: 53 | B54: 43700 | C54: Zendrive | D54: Automotive | E54: Road Safety Analytics | F54: San Francisco | G54: Xl Innovate | H54: Series B | I54: 37000000 | J54: N/A | K54: >10M | L54: =IFERROR(_xlfn.XLOOKUP(Table1[[#This Row],[Startup Name]],Reference_Tables!$A$5:$A$3048,Reference_Tables!$B$5:$B$3048,"N/A",0),"N/A") -> Mysuru | M54: =IFERROR(_xlfn.XLOOKUP(Table1[[#This Row],[Investors Name]],Reference_Tables!$E$5:$E$3048,Reference_Tables!$F$5:$F$3048,"N/A",0),"N/A") -> Angel | N54: =YEAR(Table1[[#This Row],[Date]]) -> 2019
A55: 54 | B55: 43700 | C55: Lo! Foods | D55: Consumer Goods | E55: Low Carb Food For Diabetics | F55: Bangalore | G55: Rashmi Daga (Founder, Freshmenu), Raveen Sastry (Co-Founder, Myntra) And Mitesh Shah (Finace Chief, Bookmyshow) | H55: Seed Round | I55: 500000 | J55: N/A | K55: <1M | L55: =IFERROR(_xlfn.XLOOKUP(Table1[[#This Row],[Startup Name]],Reference_Tables!$A$5:$A$3048,Reference_Tables!$B$5:$B$3048,"N/A",0),"N/A") -> New Delhi | M55: N/A | N55: =YEAR(Table1[[#This Row],[Date]]) -> 2019
A56: 55 | B56: 43700 | C56: Tala | D56: Fintech | E56: Digital Lending Platform | F56: Santa Monica | G56: Rps Ventures | H56: Series D | I56: 110000000 | J56: N/A | K56: >10M | L56: =IFERROR(_xlfn.XLOOKUP(Table1[[#This Row],[Startup Name]],Reference_Tables!$A$5:$A$3048,Reference_Tables!$B$5:$B$3048,"N/A",0),"N/A") -> Kochi | M56: =IFERROR(_xlfn.XLOOKUP(Table1[[#This Row],[Investors Name]],Reference_Tables!$E$5:$E$3048,Reference_Tables!$F$5:$F$3048,"N/A",0),"N/A") -> VC | N56: =YEAR(Table1[[#This Row],[Date]]) -> 2019
A57: 56 | B57: 43699 | C57: Indwealth | D57: Fintech | E57: Wealth Management | F57: Gurugram | G57: Tiger Global Management | H57: Venture Round | I57: 15000000 | J57: N/A | K57: >10M | L57: =IFERROR(_xlfn.XLOOKUP(Table1[[#This Row],[Startup Name]],Reference_Tables!$A$5:$A$3048,Reference_Tables!$B$5:$B$3048,"N/A",0),"N/A") -> Chandigarh | M57: =IFERROR(_xlfn.XLOOKUP(Table1[[#This Row],[Investors Name]],Reference_Tables!$E$5:$E$3048,Reference_Tables!$F$5:$F$3048,"N/A",0),"N/A") -> Angel | N57: =YEAR(Table1[[#This Row],[Date]]) -> 2019
A58: 57 | B58: 43698 | C58: Hungerbox | D58: Food And Beverage | E58: B2B Foodtech | F58: Bangalore | G58: One97 Communications Ltd. | H58: Series C | I58: 6590000 | J58: N/A | K58: 1–10M | L58: =IFERROR(_xlfn.XLOOKUP(Table1[[#This Row],[Startup Name]],Reference_Tables!$A$5:$A$3048,Reference_Tables!$B$5:$B$3048,"N/A",0),"N/A") -> Mumbai | M58: =IFERROR(_xlfn.XLOOKUP(Table1[[#This Row],[Investors Name]],Reference_Tables!$E$5:$E$3048,Reference_Tables!$F$5:$F$3048,"N/A",0),"N/A") -> Corporate | N58: =YEAR(Table1[[#This Row],[Date]]) -> 2019
A59: 58 | B59: 43700 | C59: Admitkard | D59: Edtech | E59: University Admissions | F59: Noida | G59: Growth Dna | H59: Seed Round | I59: 1000000 | J59: N/A | K59: 1–10M | L59: =IFERROR(_xlfn.XLOOKUP(Table1[[#This Row],[Startup Name]],Reference_Tables!$A$5:$A$3048,Reference_Tables!$B$5:$B$3048,"N/A",0),"N/A") -> Jaipur | M59: =IFERROR(_xlfn.XLOOKUP(Table1[[#This Row],[Investors Name]],Reference_Tables!$E$5:$E$3048,Reference_Tables!$F$5:$F$3048,"N/A",0),"N/A") -> Angel | N59: =YEAR(Table1[[#This Row],[Date]]) -> 2019
...

Sheet Reference_Tables
A1: startup city dataset | E1: investor type dataset
A4: Startup Name | B4: Startup City | E4: Investor | F4: Type
A5: Byju’S | B5: Gurugram | E5: Tiger Global Management | F5: Angel
A6: Shuttl | B6: Gurugram | E6: Susquehanna Growth Equity | F6: VC
A7: Mamaearth | B7: Chennai | E7: Sequoia Capital India | F7: VC
A8: Wealthbucket | B8: Patna | E8: Vinod Khatumal | F8: Angel
A9: Fashor | B9: Ranchi | E9: Sprout Venture Partners | F9: VC
A10: Pando | B10: Lucknow | E10: Chiratae Ventures | F10: VC
A11: Zomato | B11: Dehradun | E11: Ant Finacial | F11: Angel
A12: Ecozen | B12: Indore | E12: Sathguru Catalyzer Advisors | F12: Angel
A13: Cardekho | B13: Ranchi | E13: Ping An Global Voyager Fund | F13: VC
A14: Dhruva Space | B14: Nagpur | E14: Mumbai Angels, Ravikanth Reddy | F14: Angel
A15: Rivigo | B15: Bhopal | E15: Saif Partners, Spring Canter Investment Ltd. | F15: VC
... A3048: Couponmachine.In | B3048: Gurugram | E3048: Uk Based Group Of Angel Investors | F3048: Corporate

Sheet KPI_Calculations
A1: KEY PERFORMANCE INDICATORS (KPI)
A5: Total Funding | E5: =GETPIVOTDATA("Amount in USD",Pivot_Analysis!$M$6) -> 38143914865
A8: Total Deals | E8: =COUNTA((Data_Cleaning!C2:C3045)) -> 3044
A11: Top Investor | E11: =Pivot_Analysis!E7 -> Westbridge Capital
A14: Top City | E14: =Pivot_Analysis!Q7 -> Bangalore
A17: Peak Funding Year | E17: =Pivot_Analysis!AK7 -> 2017

Sheet Pivot_Analysis
A1: Total funding by IndustryVertical | E1: Top 10 Investors by amount | I1: Funding by Range | M1: Funding by Year | Q1: Funding By City | X1: Angle vs VC Funding | AB1: Industry Share | AG1: Number of Deals by Industry | AK1: Peak Year Funding
A6: Industry Vertical | B6: Sum of Amount in USD | E6: Investors Name | F6: Sum of Amount in USD | I6: Funding Range | J6: Count of Amount in USD | M6: Year | N6: Sum of Amount in USD | Q6: City | R6: Sum of Amount in USD | X6: Investor Type | Y6: Sum of Amount in USD | AB6: Industry | AC6: Sum of Amount in USD | AG6: Industry | AH6: Count of Startup Name | AK6: Year | AL6: Sum of Amount in USD
A7: E-Commerce | B7: 8261735693 | E7: Westbridge Capital | F7: 3952000000 | I7: 1–10M | J7: 889 | M7: 2015 | N7: 8673022368 | Q7: Bangalore | R7: 18490708863 | X7: Angel | Y7: 5887811087 | AB7: B2B | AC7: 587000000 | AG7: Consumer Internet | AH7: 942 | AK7: 2017 | AL7: 10429309730
A8: Consumer Internet | B8: 6254084245 | E8: Softbank | F8: 2500000000 | I8: <1M | J8: 752 | M8: 2016 | N8: 3828088608 | Q8: Mumbai | R8: 4940535015 | X8: Corporate | Y8: 8055130095 | AB8: Consumer Internet | AC8: 6254084245 | AG8: Technology | AH8: 478 | AK8: Grand Total | AL8: 10429309730
A9: Transportation | B9: 3916632394 | E9: Softbank Group | F9: 1467000000 | I9: >10M | J9: 432 | M9: 2017 | N9: 10429309730 | Q9: Gurugram | R9: 3876913658 | X9: VC | Y9: 22694942124 | AB9: E-Commerce | AC9: 8261735693 | AG9: E-Commerce | AH9: 300
A10: Technology | B10: 2229707930 | E10: Microsoft, Ebay, Tencent Holdings | F10: 1400000000 | M10: 2018 | N10: 5122368369 | Q10: Delhi | R10: 3302171515 | X10: Grand Total | Y10: 36637883306 | AB10: E-Commerce & M-Commerce Platform | AC10: 680000000 | AG10: N/A | AH10: 171
A11: Finace | B11: 1971438000 | E11: Vijay Shekhar Sharma | F11: 1000150000 | M11: 2019 | N11: 9700918536 | Q11: Noida | R11: 1282864000 | AB11: Finace | AC11: 1971438000 | AG11: Healthcare | AH11: 71
A12: Fintech | B12: 1224211265 | E12: Steadview Capital And Existing Investors | F12: 700000000 | M12: 2020 | N12: 390207254 | Q12: N/A | R12: 1271863868 | AB12: Fintech | AC12: 1224211265 | AG12: Finace | AH12: 62
A13: Online Marketplace | B13: 700143000 | E13: Alibaba Group, Ant Finacial | F13: 680000000 | M13: Grand Total | N13: 38143914865 | Q13: Chennai | R13: 718767000 | AB13: N/A | AC13: 1231811368 | AG13: Logistics | AH13: 32
A14: E-Commerce & M-Commerce Platform | B14: 680000000 | E14: Softbank Vision Fund | F14: 601000000 | Q14: Pune | R14: 633082000 | X14: Total Angel Funding | Y14: Total VC funding | AB14: Online Marketplace | AC14: 700143000 | AG14: Education | AH14: 24
A15: B2B | B15: 587000000 | E15: Altimeter Capital, Dst Global | F15: 585000000 | Q15: Menlo Park | R15: 450000000 | X15: =Y7 -> 5887811087 | Y15: =Y10 -> 36637883306 | AB15: Technology | AC15: 2229707930 | AG15: Food & Beverage | AH15: 23
A16: Ecommerce Marketplace | B16: 500000000 | E16: Alibaba, Foxconn, Softbank | F16: 500000000 | Q16: Hyderabad | R16: 401076230 | AB16: Transportation | AC16: 3916632394 | AG16: Ed-Tech | AH16: 15
A17: Car Aggregator & Retail Mobile App | B17: 500000000 | E17: Baillie Gifford, Falcon Edge Capital, Tiger Global, Softbank Group, Dst Global, Didi Kuaidi | F17: 500000000 | Q17: California | R17: 300000000 | AG17: Fintech | AH17: 10
A18: Health And Wellness | B18: 490686000 | E18: Grand Total | F18: 13885150000 | Q18: Kormangala | R18: 284000000 | AG18: It | AH18: 8
A19: Healthcare | B19: 418218000 | Q19: Faridabad | R19: 252000000 | AG19: Others | AH19: 6
A20: Cab Aggregator | B20: 400000000 | Q20: India/Singapore | R20: 226000000 | AG20: Real Estate | AH20: 6
A21: Education | B21: 301143000 | Q21: Tulangan | R21: 200000000 | AG21: Fin-Tech | AH21: 6
A22: Food And Beverages | B22: 300311200 | Q22: San Francisco | R22: 187000000 | AG22: Food And Beverage | AH22: 6
A23: Automation | B23: 300000000 | Q23: Jaipur | R23: 152735000 | AG23: Health And Wellness | AH23: 6
A24: Last Mile Transportation | B24: 283300000 | Q24: San Jose, | R24: 135000000 | AG24: Online Education Platform | AH24: 5
A25: Hospitality | B25: 250000000 | Q25: Ahemadabad | R25: 119980811 | AG25: Edtech | AH25: 5
A26: Logistics | B26: 242845000 | Q26: Santa Monica | R26: 110000000 | AG26: Online Food Delivery | AH26: 5
A27: Cab Rental Mobile App | B27: 225000000 | Q27: Singapore | R27: 82350000 | AG27: Logistics Tech | AH27: 5
A28: B2B Platform | B28: 225000000 | Q28: Pune / Us | R28: 68500000
A29: Saas | B29: 216000000 | Q29: Delhi / Us | R29: 67000000
A30: E-Tech | B30: 200000000 | Q30: New York | R30: 52000000
A31: Software | B31: 179500000 | Q31: India/Us | R31: 51500000
A32: Automobile | B32: 164000000 | Q32: Palo Alto | R32: 51000000
A33: Edtech | B33: 157947425 | Q33: Chandigarh | R33: 47100000
A34: Transport | B34: 152000000 | Q34: India | R34: 42000000
A35: Online Classifieds | B35: 150000000 | Q35: Taramani | R35: 38080000
A36: Fin-Tech | B36: 140700000 | Q36: Surat | R36: 36230000
A37: Agtech | B37: 140000000 | Q37: India / Us | R37: 30000000
A38: Logistics Solution Provider | B38: 137000000 | Q38: Bhubneswar | R38: 23000000
A39: Online Food Delivery | B39: 121500000 | Q39: Burnsville | R39: 18000000
... A106: Mobile Point Of Sale Payment Solution | B106: 25000000 | Q106: Grand Total | R106: 38143914865
A107: Mobile Based Pos Solution | B107: 25000000
A108: Finacial Inclusion Platform | B108: 25000000
A109: Food And Beverage | B109: 22828995
A110: Tech | B110: 21750000
...

Sheet Dashboard
AK1: Sum of Amount in USD | AM1: city | AN1: Sum of Amount in USD | AQ1: Investor | AR1: Sum of Amount in USD
AK2: 38143914865 | AM2: Bengaluru | AN2: 1784517434 | AQ2: Westbridge Capital | AR2: 3952000000

Sheet Insights
A1: 📊 Business Insights – Indian Startup Funding (2015–2020)
A6: 1️⃣ Funding Growth Pattern
A7: Funding increased significantly between 2016 and 2017, indicating strong investor confidence in Indian startups. A sharp decline in 2020 reflects pandemic-driven market uncertainty.
A11: 2️⃣ Industry Dominance
A12: E-commerce and Consumer Internet sectors attract the highest funding share, highlighting strong investor preference for scalable digital business models.
A16: 3️⃣ Geographic Concentration
A17: Bengaluru leads funding significantly, reinforcing its status as India's startup capital. Funding concentration in a few cities suggests ecosystem centralization.
A21: 4️⃣ Investor Influence
A22: Westbridge Capital and Softbank dominate funding volumes, indicating high institutional investor participation.
A26: 5️⃣ Funding Structure
A27: VC investments significantly exceed Angel funding, suggesting maturity in scaling-stage investments over early-stage backing.
A31: 6️⃣ Deal Distribution
A32: Majority of deals fall within 1–10M range, reflecting mid-sized growth-stage funding rounds.
